<?xml version="1.0"?>
<robot name="my_bot">

    <link name="world" />

    <!-- X Link -->
    <link name="x_link">
    <visual>
    <origin xyz="0 0 3" rpy="0 0 0"/>
        <geometry>
            <cylinder radius="0.01" length="0.01"/>
        </geometry>
    </visual>
    <collision>
    <origin xyz="0 0 3" rpy="0 0 0"/>
        <geometry>
            <cylinder radius="0.01" length="0.01"/>
        </geometry>
    </collision>
    <inertial>
        <origin xyz="0 0 0" rpy="0 0 0"/>
        <mass value="0.001"/>
        <inertia ixx="0.0001" ixy="0.0" ixz="0.0" 
                    iyy="0.0001" iyz="0.0" 
                    izz="0.0001"/>
    </inertial>
    </link>

    <joint name="x_joint" type="prismatic">
        <parent link="world"/>
        <child link="x_link"/>
        <origin xyz="0 0 0.05" rpy="0 0 0"/>
        <axis xyz="1 0 0"/>
        <limit lower="-100.0" upper="100.0" effort="1.0" velocity="0.5"/>
    </joint>

    
    <link name="y_link">
    <visual>
    <origin xyz="0 0 3" rpy="0 0 0"/>
        <geometry>
            <cylinder radius="0.01" length="0.01"/>
        </geometry>
    </visual>
    <collision>
    <origin xyz="0 0 3" rpy="0 0 0"/>
        <geometry>
            <cylinder radius="0.01" length="0.01"/>
        </geometry>
    </collision>
    <inertial>
        <origin xyz="0 0 0" rpy="0 0 0"/>
        <mass value="0.001"/>
        <inertia ixx="0.0001" ixy="0.0" ixz="0.0" 
                    iyy="0.0001" iyz="0.0" 
                    izz="0.0001"/>
    </inertial>
    </link>
    <!-- Y Joint -->
    <joint name="y_joint" type="prismatic">
        <parent link="x_link"/>
        <child link="y_link"/>
        <origin xyz="0 0 0" rpy="0 0 0"/>
        <axis xyz="0 1 0"/>
        <limit lower="-100.0" upper="100.0" effort="1.0" velocity="0.5"/>
    </joint>
    
    <!-- Base Link -->
    <link name="base_link">
    <visual>
        <geometry>
            <cylinder radius="0.15" length="0.1"/>
        </geometry>
    </visual>
    <collision>
        <geometry>
            <cylinder radius="0.15" length="0.1"/>
        </geometry>
    </collision>
    <inertial>
        <origin xyz="0 0 0" rpy="0 0 0"/>
        <mass value="1.0"/>
        <inertia ixx="0.00166666666667" ixy="0.0" ixz="0.0" 
                    iyy="0.00166666666667" iyz="0.0" 
                    izz="0.00166666666667"/>
    </inertial>
    </link>
    <joint name="theta_joint" type="continuous">
        <parent link="y_link"/>
        <child link="base_link"/>
        <origin xyz="0 0 0" rpy="0 0 0"/>
        <axis xyz="0 0 1"/>
    </joint>
    
    <!-- Arm Joint -->
    <joint name="arm_joint" type="revolute">
        <parent link="base_link"/>
        <child link="arm"/>
        <origin xyz="0.05 0 0.025" rpy="0 0 0"/>
        <axis xyz="0 1 0"/>
        <limit lower="-1.57079632679" upper="1.57079632679" effort="1.0" velocity="1.0"/>
    </joint>
    <link name="arm">
        <visual>
            <geometry>
                <mesh filename="package://vacumoon_simulation/description/arm.stl"/>
            </geometry>
        </visual>
        <collision>
            <geometry>
                <mesh filename="package://vacumoon_simulation/description/arm.stl"/>
            </geometry>
        </collision>
        <inertial>
            <origin xyz="0 0 0" rpy="0 0 0"/>
            <mass value="0.2"/>
            <inertia ixx="0.0001" ixy="0.0" ixz="0.0"
                     iyy="0.0001" iyz="0.0"
                     izz="0.0002"/>
        </inertial>
    </link>

    <ros2_control name="GazeboSystem" type="system">
        <hardware>
            <plugin>gazebo_ros2_control/GazeboSystem</plugin>
        </hardware>
        <joint name="theta_joint">
            <command_interface name="position"/>
            <state_interface name="position"/>
        </joint>
        <joint name="x_joint">
            <command_interface name="position"/>
            <state_interface name="position"/>
        </joint>
        <joint name="y_joint">
            <command_interface name="position"/>
            <state_interface name="position"/>
        </joint>
        <joint name="arm_joint">
            <command_interface name="position">
                <param name="min">-1.5708</param>
                <param name="max">1.5708</param>
            </command_interface>
            <state_interface name="position"/>
            <state_interface name="velocity"/>
        </joint>
    </ros2_control>

    <gazebo>
        <plugin name="gazebo_ros2_control" filename="libgazebo_ros2_control.so">
            <parameters>$(find vacumoon_simulation)/config/controllers.yaml</parameters>
        </plugin>
    </gazebo>

</robot>
