<sdf version='1.7'>
  <world name='default'>
    <light name='sun' type='directional'>
      <cast_shadows>1</cast_shadows>
      <pose>0 0 10 0 -0 0</pose>
      <diffuse>0.8 0.8 0.8 1</diffuse>
      <specular>0.2 0.2 0.2 1</specular>
      <attenuation>
        <range>1000</range>
        <constant>0.9</constant>
        <linear>0.01</linear>
        <quadratic>0.001</quadratic>
      </attenuation>
      <direction>-0.5 0.1 -0.9</direction>
      <spot>
        <inner_angle>0</inner_angle>
        <outer_angle>0</outer_angle>
        <falloff>0</falloff>
      </spot>
    </light>
    <model name='ground_plane'>
      <static>1</static>
      <link name='link'>
        <collision name='collision'>
          <geometry>
            <plane>
              <normal>0 0 1</normal>
              <size>100 100</size>
            </plane>
          </geometry>
          <surface>
            <friction>
              <ode>
                <mu>100</mu>
                <mu2>50</mu2>
              </ode>
              <torsional>
                <ode/>
              </torsional>
            </friction>
            <contact>
              <ode/>
            </contact>
            <bounce/>
          </surface>
          <max_contacts>10</max_contacts>
        </collision>
        <visual name='visual'>
          <cast_shadows>0</cast_shadows>
          <geometry>
            <plane>
              <normal>0 0 1</normal>
              <size>100 100</size>
            </plane>
          </geometry>
          <material>
            <script>
              <uri>file://media/materials/scripts/gazebo.material</uri>
              <name>Gazebo/Grey</name>
            </script>
          </material>
        </visual>
        <self_collide>0</self_collide>
        <enable_wind>0</enable_wind>
        <kinematic>0</kinematic>
      </link>
    </model>
    <gravity>0 0 -9.8</gravity>
    <magnetic_field>6e-06 2.3e-05 -4.2e-05</magnetic_field>
    <atmosphere type='adiabatic'/>
    <physics type='ode'>
      <max_step_size>0.001</max_step_size>
      <real_time_factor>1</real_time_factor>
      <real_time_update_rate>1000</real_time_update_rate>
    </physics>
    <scene>
      <ambient>0.4 0.4 0.4 1</ambient>
      <background>0.7 0.7 0.7 1</background>
      <shadows>1</shadows>
    </scene>
    <audio>
      <device>default</device>
    </audio>
    <wind/>
    <spherical_coordinates>
      <surface_model>EARTH_WGS84</surface_model>
      <latitude_deg>0</latitude_deg>
      <longitude_deg>0</longitude_deg>
      <elevation>0</elevation>
      <heading_deg>0</heading_deg>
    </spherical_coordinates>
    <model name='cube_obstacle_0'>
      <link name='link'>
        <pose>0 0 0.5 0 -0 0</pose>
        <collision name='collision'>
          <geometry>
            <mesh>
              <uri>model://cube_obstacle/meshes/cube.stl</uri>
            </mesh>
          </geometry>
          <max_contacts>10</max_contacts>
          <surface>
            <contact>
              <ode/>
            </contact>
            <bounce/>
            <friction>
              <torsional>
                <ode/>
              </torsional>
              <ode/>
            </friction>
          </surface>
        </collision>
        <visual name='visual'>
          <geometry>
            <mesh>
              <uri>model://cube_obstacle/meshes/cube.stl</uri>
            </mesh>
          </geometry>
        </visual>
        <self_collide>0</self_collide>
        <inertial>
          <pose>0 0 0 0 -0 0</pose>
          <inertia>
            <ixx>1</ixx>
            <ixy>0</ixy>
            <ixz>0</ixz>
            <iyy>1</iyy>
            <iyz>0</iyz>
            <izz>1</izz>
          </inertia>
          <mass>1</mass>
        </inertial>
        <enable_wind>0</enable_wind>
        <kinematic>0</kinematic>
      </link>
      <pose>2.73676 2.7683 0 0 -0 0</pose>
    </model>
    <state world_name='default'>
      <sim_time>248 649000000</sim_time>
      <real_time>191 711923154</real_time>
      <wall_time>1737298360 245808509</wall_time>
      <iterations>191536</iterations>
      <model name='cube_obstacle_0'>
        <pose>2.51679 4.47749 -0.5 -0 -0 -0</pose>
        <scale>1 1 1</scale>
        <link name='link'>
          <pose>2.51679 4.47749 0 -0 -0 -0</pose>
          <velocity>0 0 0 0 -0 0</velocity>
          <acceleration>-0 1e-06 2.90704 1.80781 1.33874 -3.14159</acceleration>
          <wrench>-0 1e-06 2.90704 0 -0 0</wrench>
        </link>
      </model>
      <model name='cube_obstacle_0_clone'>
        <pose>4.52945 5.49802 -0.5 -0 -0 -0</pose>
        <scale>1 1 1</scale>
        <link name='link'>
          <pose>4.52945 5.49802 0 -0 -0 -0</pose>
          <velocity>0 0 0 0 -0 0</velocity>
          <acceleration>-0 1e-06 2.90704 1.80781 1.33874 -3.14159</acceleration>
          <wrench>-0 1e-06 2.90704 0 -0 0</wrench>
        </link>
      </model>
      <model name='cube_obstacle_0_clone_0'>
        <pose>6.51221 7.48777 -0.5 -0 -0 -0</pose>
        <scale>1 1 1</scale>
        <link name='link'>
          <pose>6.51221 7.48777 0 -0 -0 -0</pose>
          <velocity>0 0 0 0 -0 0</velocity>
          <acceleration>-0 1e-06 2.90704 1.80781 1.33874 -3.14159</acceleration>
          <wrench>-0 1e-06 2.90704 0 -0 0</wrench>
        </link>
      </model>
      <model name='cube_obstacle_0_clone_1'>
        <pose>7.49526 4.50697 -0.5 -0 -0 -0</pose>
        <scale>1 1 1</scale>
        <link name='link'>
          <pose>7.49526 4.50697 0 -0 -0 -0</pose>
          <velocity>0 0 0 0 -0 0</velocity>
          <acceleration>-0 1e-06 2.90704 1.80781 1.33874 -3.14159</acceleration>
          <wrench>-0 1e-06 2.90704 0 -0 0</wrench>
        </link>
      </model>
      <model name='cube_obstacle_0_clone_2'>
        <pose>4.50356 1.48626 -0.5 -0 -0 -0</pose>
        <scale>1 1 1</scale>
        <link name='link'>
          <pose>4.50356 1.48626 0 -0 -0 -0</pose>
          <velocity>0 0 0 0 -0 0</velocity>
          <acceleration>-0 1e-06 2.90704 1.80781 1.33874 -3.14159</acceleration>
          <wrench>-0 1e-06 2.90704 0 -0 0</wrench>
        </link>
      </model>
      <model name='cube_obstacle_0_clone_3'>
        <pose>2.52027 2.47172 -0.5 -0 -0 -0</pose>
        <scale>1 1 1</scale>
        <link name='link'>
          <pose>2.52027 2.47172 0 -0 -0 -0</pose>
          <velocity>0 0 0 0 -0 0</velocity>
          <acceleration>-0 1e-06 2.90704 1.80781 1.33874 -3.14159</acceleration>
          <wrench>-0 1e-06 2.90704 0 -0 0</wrench>
        </link>
      </model>
      <model name='cube_obstacle_0_clone_4'>
        <pose>7.47965 1.49169 -0.5 -0 -0 -0</pose>
        <scale>1 1 1</scale>
        <link name='link'>
          <pose>7.47965 1.49169 0 -0 -0 -0</pose>
          <velocity>0 0 0 0 -0 0</velocity>
          <acceleration>-0 1e-06 2.90704 1.80781 1.33874 -3.14159</acceleration>
          <wrench>-0 1e-06 2.90704 0 -0 0</wrench>
        </link>
      </model>
      <model name='cube_obstacle_0_clone_5'>
        <pose>9.5001 0.50975 -0.5 -0 -0 -0</pose>
        <scale>1 1 1</scale>
        <link name='link'>
          <pose>9.5001 0.50975 0 -0 -0 -0</pose>
          <velocity>0 0 0 0 -0 0</velocity>
          <acceleration>-0 1e-06 2.90704 1.80781 1.33874 -3.14159</acceleration>
          <wrench>-0 1e-06 2.90704 0 -0 0</wrench>
        </link>
      </model>
      <model name='cube_obstacle_0_clone_6'>
        <pose>0.534818 8.49904 -0.5 -0 -0 -0</pose>
        <scale>1 1 1</scale>
        <link name='link'>
          <pose>0.534818 8.49904 0 -0 -0 -0</pose>
          <velocity>0 0 0 0 -0 0</velocity>
          <acceleration>-0 1e-06 2.90704 1.80781 1.33874 -3.14159</acceleration>
          <wrench>-0 1e-06 2.90704 0 -0 0</wrench>
        </link>
      </model>
      <model name='cube_obstacle_0_clone_7'>
        <pose>3.50836 7.49863 -0.5 -0 -0 -0</pose>
        <scale>1 1 1</scale>
        <link name='link'>
          <pose>3.50836 7.49863 0 -0 -0 -0</pose>
          <velocity>0 0 0 0 -0 0</velocity>
          <acceleration>-0 1e-06 2.76461 2.21554 1.46161 -3.14159</acceleration>
          <wrench>-0 1e-06 2.76461 0 -0 0</wrench>
        </link>
      </model>
      <model name='cube_obstacle_0_clone_8'>
        <pose>5.48954 9.47593 -0.500002 3e-06 1e-06 -0</pose>
        <scale>1 1 1</scale>
        <link name='link'>
          <pose>5.48954 9.47593 -2e-06 3e-06 1e-06 -0</pose>
          <velocity>0 0 0 0 -0 0</velocity>
          <acceleration>1e-06 0 -3.26666 0.125079 -0.125079 3.14159</acceleration>
          <wrench>1e-06 0 -3.26666 0 -0 0</wrench>
        </link>
      </model>
      <model name='ground_plane'>
        <pose>0 0 0 0 -0 0</pose>
        <scale>1 1 1</scale>
        <link name='link'>
          <pose>0 0 0 0 -0 0</pose>
          <velocity>0 0 0 0 -0 0</velocity>
          <acceleration>0 0 0 0 -0 0</acceleration>
          <wrench>0 0 0 0 -0 0</wrench>
        </link>
      </model>
      <model name='my_bot'>
        <pose>4e-06 -0 1e-06 -7e-06 -7e-06 -0</pose>
        <scale>1 1 1</scale>
        <link name='arm'>
          <pose>0.050004 -5e-06 0.074993 3.5e-05 -2.4e-05 -2.2e-05</pose>
          <velocity>0.005053 -0.004976 -0.003276 0.06662 -0.018493 0.000165</velocity>
          <acceleration>8.93699 -8.78285 -4.16082 -2.97536 -0.001858 0.165887</acceleration>
          <wrench>1.7874 -1.75657 -0.832164 0 -0 0</wrench>
        </link>
        <link name='base_link'>
          <pose>3e-06 -3e-06 0.049995 3.2e-05 3.3e-05 -2.4e-05</pose>
          <velocity>0.003357 -0.003317 7.2e-05 0.066357 0.067101 1.6e-05</velocity>
          <acceleration>6.77793 -6.66497 0.111637 -0.096906 -0.769108 -3.12513</acceleration>
          <wrench>6.77793 -6.66497 0.111637 0 -0 0</wrench>
        </link>
        <link name='x_link'>
          <pose>3e-06 -0 0.050001 -7e-06 -7e-06 -0</pose>
          <velocity>0.003385 0 -1.5e-05 -0.013697 -0.01376 0</velocity>
          <acceleration>3.38525 2e-06 -0.014689 0.778439 -0.623078 -3.14158</acceleration>
          <wrench>0.003385 0 -1.5e-05 0 -0 0</wrench>
        </link>
        <link name='y_link'>
          <pose>3e-06 -3e-06 0.049999 1e-05 1e-05 0</pose>
          <velocity>0.003387 -0.003319 2e-05 0.018234 0.018316 0</velocity>
          <acceleration>3.38703 -3.31887 0.019696 -1.09661 -0.892419 -1.1e-05</acceleration>
          <wrench>0.003387 -0.003319 2e-05 0 -0 0</wrench>
        </link>
      </model>
      <light name='sun'>
        <pose>0 0 10 0 -0 0</pose>
      </light>
    </state>
    <model name='my_bot'>
      <joint name='x_joint' type='prismatic'>
        <pose relative_to='__model__'>0 0 0.05 0 -0 0</pose>
        <parent>world</parent>
        <child>x_link</child>
        <axis>
          <xyz>1 0 0</xyz>
          <limit>
            <lower>-100</lower>
            <upper>100</upper>
            <effort>1</effort>
            <velocity>0.5</velocity>
          </limit>
          <dynamics>
            <spring_reference>0</spring_reference>
            <spring_stiffness>0</spring_stiffness>
          </dynamics>
        </axis>
      </joint>
      <link name='x_link'>
        <pose relative_to='x_joint'>0 0 0 0 -0 0</pose>
        <inertial>
          <pose>0 0 0 0 -0 0</pose>
          <mass>0.001</mass>
          <inertia>
            <ixx>0.0001</ixx>
            <ixy>0</ixy>
            <ixz>0</ixz>
            <iyy>0.0001</iyy>
            <iyz>0</iyz>
            <izz>0.0001</izz>
          </inertia>
        </inertial>
        <collision name='x_link_collision'>
          <pose>0 0 3 0 -0 0</pose>
          <geometry>
            <cylinder>
              <length>0.01</length>
              <radius>0.01</radius>
            </cylinder>
          </geometry>
          <max_contacts>10</max_contacts>
          <surface>
            <contact>
              <ode/>
            </contact>
            <bounce/>
            <friction>
              <torsional>
                <ode/>
              </torsional>
              <ode/>
            </friction>
          </surface>
        </collision>
        <visual name='x_link_visual'>
          <pose>0 0 3 0 -0 0</pose>
          <geometry>
            <cylinder>
              <length>0.01</length>
              <radius>0.01</radius>
            </cylinder>
          </geometry>
        </visual>
        <self_collide>0</self_collide>
        <enable_wind>0</enable_wind>
        <kinematic>0</kinematic>
      </link>
      <joint name='y_joint' type='prismatic'>
        <pose relative_to='x_link'>0 0 0 0 -0 0</pose>
        <parent>x_link</parent>
        <child>y_link</child>
        <axis>
          <xyz>0 1 0</xyz>
          <limit>
            <lower>-100</lower>
            <upper>100</upper>
            <effort>1</effort>
            <velocity>0.5</velocity>
          </limit>
          <dynamics>
            <spring_reference>0</spring_reference>
            <spring_stiffness>0</spring_stiffness>
          </dynamics>
        </axis>
      </joint>
      <link name='y_link'>
        <pose relative_to='y_joint'>0 0 0 0 -0 0</pose>
        <inertial>
          <pose>0 0 0 0 -0 0</pose>
          <mass>0.001</mass>
          <inertia>
            <ixx>0.0001</ixx>
            <ixy>0</ixy>
            <ixz>0</ixz>
            <iyy>0.0001</iyy>
            <iyz>0</iyz>
            <izz>0.0001</izz>
          </inertia>
        </inertial>
        <collision name='y_link_collision'>
          <pose>0 0 3 0 -0 0</pose>
          <geometry>
            <cylinder>
              <length>0.01</length>
              <radius>0.01</radius>
            </cylinder>
          </geometry>
          <max_contacts>10</max_contacts>
          <surface>
            <contact>
              <ode/>
            </contact>
            <bounce/>
            <friction>
              <torsional>
                <ode/>
              </torsional>
              <ode/>
            </friction>
          </surface>
        </collision>
        <visual name='y_link_visual'>
          <pose>0 0 3 0 -0 0</pose>
          <geometry>
            <cylinder>
              <length>0.01</length>
              <radius>0.01</radius>
            </cylinder>
          </geometry>
        </visual>
        <self_collide>0</self_collide>
        <enable_wind>0</enable_wind>
        <kinematic>0</kinematic>
      </link>
      <joint name='theta_joint' type='revolute'>
        <pose relative_to='y_link'>0 0 0 0 -0 0</pose>
        <parent>y_link</parent>
        <child>base_link</child>
        <axis>
          <xyz>0 0 1</xyz>
          <limit>
            <lower>-1e+16</lower>
            <upper>1e+16</upper>
          </limit>
          <dynamics>
            <spring_reference>0</spring_reference>
            <spring_stiffness>0</spring_stiffness>
          </dynamics>
        </axis>
      </joint>
      <link name='base_link'>
        <pose relative_to='theta_joint'>0 0 0 0 -0 0</pose>
        <inertial>
          <pose>0 0 0 0 -0 0</pose>
          <mass>1</mass>
          <inertia>
            <ixx>0.00166667</ixx>
            <ixy>0</ixy>
            <ixz>0</ixz>
            <iyy>0.00166667</iyy>
            <iyz>0</iyz>
            <izz>0.00166667</izz>
          </inertia>
        </inertial>
        <collision name='base_link_collision'>
          <pose>0 0 0 0 -0 0</pose>
          <geometry>
            <cylinder>
              <length>0.1</length>
              <radius>0.15</radius>
            </cylinder>
          </geometry>
          <max_contacts>10</max_contacts>
          <surface>
            <contact>
              <ode/>
            </contact>
            <bounce/>
            <friction>
              <torsional>
                <ode/>
              </torsional>
              <ode/>
            </friction>
          </surface>
        </collision>
        <visual name='base_link_visual'>
          <pose>0 0 0 0 -0 0</pose>
          <geometry>
            <cylinder>
              <length>0.1</length>
              <radius>0.15</radius>
            </cylinder>
          </geometry>
        </visual>
        <self_collide>0</self_collide>
        <enable_wind>0</enable_wind>
        <kinematic>0</kinematic>
      </link>
      <joint name='arm_joint' type='revolute'>
        <pose relative_to='base_link'>0.05 0 0.025 0 -0 0</pose>
        <parent>base_link</parent>
        <child>arm</child>
        <axis>
          <xyz>0 1 0</xyz>
          <limit>
            <lower>-1.5708</lower>
            <upper>1.5708</upper>
            <effort>1</effort>
            <velocity>1</velocity>
          </limit>
          <dynamics>
            <spring_reference>0</spring_reference>
            <spring_stiffness>0</spring_stiffness>
          </dynamics>
        </axis>
      </joint>
      <link name='arm'>
        <pose relative_to='arm_joint'>0 0 0 0 -0 0</pose>
        <inertial>
          <pose>0 0 0 0 -0 0</pose>
          <mass>0.2</mass>
          <inertia>
            <ixx>0.0001</ixx>
            <ixy>0</ixy>
            <ixz>0</ixz>
            <iyy>0.0001</iyy>
            <iyz>0</iyz>
            <izz>0.0002</izz>
          </inertia>
        </inertial>
        <collision name='arm_collision'>
          <pose>0 0 0 0 -0 0</pose>
          <geometry>
            <mesh>
              <scale>1 1 1</scale>
              <uri>model://vacumoon_simulation/description/arm.stl</uri>
            </mesh>
          </geometry>
          <max_contacts>10</max_contacts>
          <surface>
            <contact>
              <ode/>
            </contact>
            <bounce/>
            <friction>
              <torsional>
                <ode/>
              </torsional>
              <ode/>
            </friction>
          </surface>
        </collision>
        <visual name='arm_visual'>
          <pose>0 0 0 0 -0 0</pose>
          <geometry>
            <mesh>
              <scale>1 1 1</scale>
              <uri>model://vacumoon_simulation/description/arm.stl</uri>
            </mesh>
          </geometry>
        </visual>
        <self_collide>0</self_collide>
        <enable_wind>0</enable_wind>
        <kinematic>0</kinematic>
      </link>
      <static>0</static>
      <plugin name='gazebo_ros2_control' filename='libgazebo_ros2_control.so'>
        <parameters>/home/max/vacumoon_ws/install/vacumoon_simulation/share/vacumoon_simulation/config/controllers.yaml</parameters>
      </plugin>
      <pose>0 0 0 0 -0 0</pose>
    </model>
    <model name='cube_obstacle_0_clone'>
      <link name='link'>
        <pose>0 0 0.5 0 -0 0</pose>
        <collision name='collision'>
          <geometry>
            <mesh>
              <uri>model://cube_obstacle/meshes/cube.stl</uri>
            </mesh>
          </geometry>
          <max_contacts>10</max_contacts>
          <surface>
            <contact>
              <ode/>
            </contact>
            <bounce/>
            <friction>
              <torsional>
                <ode/>
              </torsional>
              <ode/>
            </friction>
          </surface>
        </collision>
        <visual name='visual'>
          <geometry>
            <mesh>
              <uri>model://cube_obstacle/meshes/cube.stl</uri>
            </mesh>
          </geometry>
        </visual>
        <self_collide>0</self_collide>
        <inertial>
          <pose>0 0 0 0 -0 0</pose>
          <inertia>
            <ixx>1</ixx>
            <ixy>0</ixy>
            <ixz>0</ixz>
            <iyy>1</iyy>
            <iyz>0</iyz>
            <izz>1</izz>
          </inertia>
          <mass>1</mass>
        </inertial>
        <enable_wind>0</enable_wind>
        <kinematic>0</kinematic>
      </link>
      <pose>4.52945 5.49802 -0.5 -0 -0 -0</pose>
    </model>
    <model name='cube_obstacle_0_clone_0'>
      <link name='link'>
        <pose>0 0 0.5 0 -0 0</pose>
        <collision name='collision'>
          <geometry>
            <mesh>
              <uri>model://cube_obstacle/meshes/cube.stl</uri>
            </mesh>
          </geometry>
          <max_contacts>10</max_contacts>
          <surface>
            <contact>
              <ode/>
            </contact>
            <bounce/>
            <friction>
              <torsional>
                <ode/>
              </torsional>
              <ode/>
            </friction>
          </surface>
        </collision>
        <visual name='visual'>
          <geometry>
            <mesh>
              <uri>model://cube_obstacle/meshes/cube.stl</uri>
            </mesh>
          </geometry>
        </visual>
        <self_collide>0</self_collide>
        <inertial>
          <pose>0 0 0 0 -0 0</pose>
          <inertia>
            <ixx>1</ixx>
            <ixy>0</ixy>
            <ixz>0</ixz>
            <iyy>1</iyy>
            <iyz>0</iyz>
            <izz>1</izz>
          </inertia>
          <mass>1</mass>
        </inertial>
        <enable_wind>0</enable_wind>
        <kinematic>0</kinematic>
      </link>
      <pose>6.51221 7.48777 -0.5 -0 -0 -0</pose>
    </model>
    <model name='cube_obstacle_0_clone_1'>
      <link name='link'>
        <pose>0 0 0.5 0 -0 0</pose>
        <collision name='collision'>
          <geometry>
            <mesh>
              <uri>model://cube_obstacle/meshes/cube.stl</uri>
            </mesh>
          </geometry>
          <max_contacts>10</max_contacts>
          <surface>
            <contact>
              <ode/>
            </contact>
            <bounce/>
            <friction>
              <torsional>
                <ode/>
              </torsional>
              <ode/>
            </friction>
          </surface>
        </collision>
        <visual name='visual'>
          <geometry>
            <mesh>
              <uri>model://cube_obstacle/meshes/cube.stl</uri>
            </mesh>
          </geometry>
        </visual>
        <self_collide>0</self_collide>
        <inertial>
          <pose>0 0 0 0 -0 0</pose>
          <inertia>
            <ixx>1</ixx>
            <ixy>0</ixy>
            <ixz>0</ixz>
            <iyy>1</iyy>
            <iyz>0</iyz>
            <izz>1</izz>
          </inertia>
          <mass>1</mass>
        </inertial>
        <enable_wind>0</enable_wind>
        <kinematic>0</kinematic>
      </link>
      <pose>7.49526 4.50697 -0.5 -0 -0 -0</pose>
    </model>
    <model name='cube_obstacle_0_clone_2'>
      <link name='link'>
        <pose>0 0 0.5 0 -0 0</pose>
        <collision name='collision'>
          <geometry>
            <mesh>
              <uri>model://cube_obstacle/meshes/cube.stl</uri>
            </mesh>
          </geometry>
          <max_contacts>10</max_contacts>
          <surface>
            <contact>
              <ode/>
            </contact>
            <bounce/>
            <friction>
              <torsional>
                <ode/>
              </torsional>
              <ode/>
            </friction>
          </surface>
        </collision>
        <visual name='visual'>
          <geometry>
            <mesh>
              <uri>model://cube_obstacle/meshes/cube.stl</uri>
            </mesh>
          </geometry>
        </visual>
        <self_collide>0</self_collide>
        <inertial>
          <pose>0 0 0 0 -0 0</pose>
          <inertia>
            <ixx>1</ixx>
            <ixy>0</ixy>
            <ixz>0</ixz>
            <iyy>1</iyy>
            <iyz>0</iyz>
            <izz>1</izz>
          </inertia>
          <mass>1</mass>
        </inertial>
        <enable_wind>0</enable_wind>
        <kinematic>0</kinematic>
      </link>
      <pose>4.50356 1.48626 -0.5 -0 -0 -0</pose>
    </model>
    <model name='cube_obstacle_0_clone_3'>
      <link name='link'>
        <pose>0 0 0.5 0 -0 0</pose>
        <collision name='collision'>
          <geometry>
            <mesh>
              <uri>model://cube_obstacle/meshes/cube.stl</uri>
            </mesh>
          </geometry>
          <max_contacts>10</max_contacts>
          <surface>
            <contact>
              <ode/>
            </contact>
            <bounce/>
            <friction>
              <torsional>
                <ode/>
              </torsional>
              <ode/>
            </friction>
          </surface>
        </collision>
        <visual name='visual'>
          <geometry>
            <mesh>
              <uri>model://cube_obstacle/meshes/cube.stl</uri>
            </mesh>
          </geometry>
        </visual>
        <self_collide>0</self_collide>
        <inertial>
          <pose>0 0 0 0 -0 0</pose>
          <inertia>
            <ixx>1</ixx>
            <ixy>0</ixy>
            <ixz>0</ixz>
            <iyy>1</iyy>
            <iyz>0</iyz>
            <izz>1</izz>
          </inertia>
          <mass>1</mass>
        </inertial>
        <enable_wind>0</enable_wind>
        <kinematic>0</kinematic>
      </link>
      <pose>2.52027 2.47172 -0.5 -0 -0 -0</pose>
    </model>
    <model name='cube_obstacle_0_clone_4'>
      <link name='link'>
        <pose>0 0 0.5 0 -0 0</pose>
        <collision name='collision'>
          <geometry>
            <mesh>
              <uri>model://cube_obstacle/meshes/cube.stl</uri>
            </mesh>
          </geometry>
          <max_contacts>10</max_contacts>
          <surface>
            <contact>
              <ode/>
            </contact>
            <bounce/>
            <friction>
              <torsional>
                <ode/>
              </torsional>
              <ode/>
            </friction>
          </surface>
        </collision>
        <visual name='visual'>
          <geometry>
            <mesh>
              <uri>model://cube_obstacle/meshes/cube.stl</uri>
            </mesh>
          </geometry>
        </visual>
        <self_collide>0</self_collide>
        <inertial>
          <pose>0 0 0 0 -0 0</pose>
          <inertia>
            <ixx>1</ixx>
            <ixy>0</ixy>
            <ixz>0</ixz>
            <iyy>1</iyy>
            <iyz>0</iyz>
            <izz>1</izz>
          </inertia>
          <mass>1</mass>
        </inertial>
        <enable_wind>0</enable_wind>
        <kinematic>0</kinematic>
      </link>
      <pose>7.47965 1.49169 -0.5 -0 -0 -0</pose>
    </model>
    <model name='cube_obstacle_0_clone_5'>
      <link name='link'>
        <pose>0 0 0.5 0 -0 0</pose>
        <collision name='collision'>
          <geometry>
            <mesh>
              <uri>model://cube_obstacle/meshes/cube.stl</uri>
            </mesh>
          </geometry>
          <max_contacts>10</max_contacts>
          <surface>
            <contact>
              <ode/>
            </contact>
            <bounce/>
            <friction>
              <torsional>
                <ode/>
              </torsional>
              <ode/>
            </friction>
          </surface>
        </collision>
        <visual name='visual'>
          <geometry>
            <mesh>
              <uri>model://cube_obstacle/meshes/cube.stl</uri>
            </mesh>
          </geometry>
        </visual>
        <self_collide>0</self_collide>
        <inertial>
          <pose>0 0 0 0 -0 0</pose>
          <inertia>
            <ixx>1</ixx>
            <ixy>0</ixy>
            <ixz>0</ixz>
            <iyy>1</iyy>
            <iyz>0</iyz>
            <izz>1</izz>
          </inertia>
          <mass>1</mass>
        </inertial>
        <enable_wind>0</enable_wind>
        <kinematic>0</kinematic>
      </link>
      <pose>9.5001 0.50975 -0.5 -0 -0 -0</pose>
    </model>
    <model name='cube_obstacle_0_clone_6'>
      <link name='link'>
        <pose>0 0 0.5 0 -0 0</pose>
        <collision name='collision'>
          <geometry>
            <mesh>
              <uri>model://cube_obstacle/meshes/cube.stl</uri>
            </mesh>
          </geometry>
          <max_contacts>10</max_contacts>
          <surface>
            <contact>
              <ode/>
            </contact>
            <bounce/>
            <friction>
              <torsional>
                <ode/>
              </torsional>
              <ode/>
            </friction>
          </surface>
        </collision>
        <visual name='visual'>
          <geometry>
            <mesh>
              <uri>model://cube_obstacle/meshes/cube.stl</uri>
            </mesh>
          </geometry>
        </visual>
        <self_collide>0</self_collide>
        <inertial>
          <pose>0 0 0 0 -0 0</pose>
          <inertia>
            <ixx>1</ixx>
            <ixy>0</ixy>
            <ixz>0</ixz>
            <iyy>1</iyy>
            <iyz>0</iyz>
            <izz>1</izz>
          </inertia>
          <mass>1</mass>
        </inertial>
        <enable_wind>0</enable_wind>
        <kinematic>0</kinematic>
      </link>
      <pose>0.534818 8.49904 -0.5 -0 -0 -0</pose>
    </model>
    <model name='cube_obstacle_0_clone_7'>
      <link name='link'>
        <pose>0 0 0.5 0 -0 0</pose>
        <collision name='collision'>
          <geometry>
            <mesh>
              <uri>model://cube_obstacle/meshes/cube.stl</uri>
            </mesh>
          </geometry>
          <max_contacts>10</max_contacts>
          <surface>
            <contact>
              <ode/>
            </contact>
            <bounce/>
            <friction>
              <torsional>
                <ode/>
              </torsional>
              <ode/>
            </friction>
          </surface>
        </collision>
        <visual name='visual'>
          <geometry>
            <mesh>
              <uri>model://cube_obstacle/meshes/cube.stl</uri>
            </mesh>
          </geometry>
        </visual>
        <self_collide>0</self_collide>
        <inertial>
          <pose>0 0 0 0 -0 0</pose>
          <inertia>
            <ixx>1</ixx>
            <ixy>0</ixy>
            <ixz>0</ixz>
            <iyy>1</iyy>
            <iyz>0</iyz>
            <izz>1</izz>
          </inertia>
          <mass>1</mass>
        </inertial>
        <enable_wind>0</enable_wind>
        <kinematic>0</kinematic>
      </link>
      <pose>3.50836 7.49863 -0.5 -0 -0 -0</pose>
    </model>
    <model name='cube_obstacle_0_clone_8'>
      <link name='link'>
        <pose>0 0 0.5 0 -0 0</pose>
        <collision name='collision'>
          <geometry>
            <mesh>
              <uri>model://cube_obstacle/meshes/cube.stl</uri>
            </mesh>
          </geometry>
          <max_contacts>10</max_contacts>
          <surface>
            <contact>
              <ode/>
            </contact>
            <bounce/>
            <friction>
              <torsional>
                <ode/>
              </torsional>
              <ode/>
            </friction>
          </surface>
        </collision>
        <visual name='visual'>
          <geometry>
            <mesh>
              <uri>model://cube_obstacle/meshes/cube.stl</uri>
            </mesh>
          </geometry>
        </visual>
        <self_collide>0</self_collide>
        <inertial>
          <pose>0 0 0 0 -0 0</pose>
          <inertia>
            <ixx>1</ixx>
            <ixy>0</ixy>
            <ixz>0</ixz>
            <iyy>1</iyy>
            <iyz>0</iyz>
            <izz>1</izz>
          </inertia>
          <mass>1</mass>
        </inertial>
        <enable_wind>0</enable_wind>
        <kinematic>0</kinematic>
      </link>
      <pose>5.48954 9.47593 -0.5 -0 -0 -0</pose>
    </model>
    <gui fullscreen='0'>
      <camera name='user_camera'>
        <pose>4.43161 1.25402 13.9477 0 1.3978 1.58019</pose>
        <view_controller>orbit</view_controller>
        <projection_type>perspective</projection_type>
      </camera>
    </gui>
  </world>
</sdf>
